Workbook

Sheet Detailed adjustments
A1: ABCD
A3: Client name: | D3: Name | E3: Date
A4: Period: | C4: Prepared by:
A5: Summary of detailed adjustments for CIT calculation | C5: Reviewed by:
D8: USD/VND
A9: Ref. | B9: Description | C9: Amount | E9: Code
C10: USD | D10: VND
A11: A | B11: Profit/(loss) before tax and adjustment | C11: 0 | D11: 0 | E11: A1
A13: B | B13: Adjustments
A15: I | B15: Incremental adjustment of taxable income | C15: =C17+C19+C21+C47+C49 -> 0 | D15: =D17+D19+D21+D47+D49 -> 0 | E15: B1
A17: 1 | B17: Incremental adjustments of taxable revenue | C17: 0 | D17: 0 | E17: B2
A19: 2 | B19: Expenses relevant to decremental adjustments of taxable revenue | C19: 0 | D19: 0 | E19: B3
A21: 3 | B21: Non-deductible expenses when determining taxable income | C21: =C23+C27+C29+C31+C33+C35+C37+C41+C43+C45 -> 0 | D21: =D23+D27+D29+D31+D33+D35+D37+D41+D43+D45 -> 0 | E21: B4
A23: =A21+0.1 -> 3.1 | B23: Non-deductible depreciation expense | C23: 0 | D23: =ROUND(C23*$E$8,0) -> 0 | E23: B4.1
A25: 3.2 | B25: Non-deductible cost of raw materials, materials, fuel, power, or goods | C25: 0 | D25: =ROUND(C25*$E$8,0) -> 0 | E25: B4.2
A27: =A25+0.1 -> 3.3 | B27: Non-deductible interest expenses | C27: 0 | D27: =ROUND(C27*$E$8,0) -> 0 | E27: B4.3
A29: =A27+0.1 -> 3.4 | B29: Expenses without invoices | C29: 0 | D29: =ROUND(C29*$E$8,0) -> 0 | E29: B4.4
A31: =A29+0.1 -> 3.5 | B31: Collection of backtaxes and penalties | C31: 0 | D31: =ROUND(C31*$E$8,0) -> 0 | E31: B4.5
A33: =A31+0.1 -> 3.6 | B33: Non-business expenses | C33: 0 | D33: =ROUND(C33*$E$8,0) -> 0 | E33: B4.6
A35: =A33+0.1 -> 3.7 | B35: Non-deductible employment related costs | C35: 0 | D35: =ROUND(C35*$E$8,0) -> 0 | E35: B4.7
A37: =A35+0.1 -> 3.8 | B37: Non-deductible accrued expenses | C37: 0 | D37: =ROUND(C37*$E$8,0) -> 0 | E37: B4.8
A39: 3.9 | B39: Non-deductible provisional expenses | C39: 0 | D39: =ROUND(C39*$E$8,0) -> 0 | E39: B4.9
A41: 3.10 | B41: Non-deductible management fee | C41: 0 | D41: 0 | E41: B4.10
A43: 3.11 | B43: Non-deductible unrealised foreign exchange loss | E43: B4.11
A45: 3.12 | B45: Non-deductible advertisement and promotion (A&P) expenses | E45: B4.12
A47: 4 | B47: Foreign tax payment for income generated overseas | C47: 0 | D47: 0 | E47: B5
A49: 5 | B49: Other adjustments | C49: =SUM(C50:C56) -> 0 | D49: =ROUND(C49*$E$8,0) -> 0 | E49: B6
A51: 5.1 | B51: Non-deductible staff uniform allowance | C51: 0 | E51: B6.1
A53: 5.2 | B53: Non-deductible per-diem allowances | C53: 0 | E53: B6.2
A55: 5.3 | B55: xxx | C55: 0
A57: II | B57: Decremental adjustment of taxable income | C57: =C59+C61+C63+C65 -> 0 | D57: =D59+D61+D63+D65 -> 0 | E57: B7
A59: 1 | B59: Revenue from business activities that are qualified for tax exemption | C59: 0 | D59: 0 | E59: B8
A61: 2 | B61: Deduction of revenue taxed in the previous year | C61: 0 | D61: 0 | E61: B9
A63: 3 | B63: Expenses relevant to incremental adjustment of taxable revenue | C63: 0 | D63: 0 | E63: B10
A65: 4 | B65: Other decremental adjustment to taxable income | C65: 0 | D65: =D67+D69 -> 0 | E65: B11
A67: =A65+0.1 -> 4.1 | B67: Non-taxable unrealised foreign exchange gain | C67: 0 | D67: =ROUND(C67*$E$8,0) -> 0 | E67: B11.1
A69: =A67+0.1 -> 4.2 | B69: Other adjustments | C69: 0 | D69: =ROUND(C69*$E$8,0) -> 0 | E69: B11.2
A71: B | B71: Taxable income after adjustments | C71: =C11+C15-C57 -> 0 | D71: =D11+D15-D57 -> 0 | E71: B12

Sheet B2
A1: ABCD | H1: WP-B2
A3: Company name: | G3: Name | H3: Date
A4: Period: | F4: Prepared by:
F5: Reviewed by:
A7: Item B2 - Incremental adjustment of taxable revenue
A27: 1. Approach guidance | G27: Completed | H27: Reviewed
A29: 1.1 | B29: Discuss with the Company's management and review its audited financial statements to understand | G29: o | H29: o
B30: its accounting policies on sales recognition. Determine if the Company's accounting policies on its sales recognition
B31: is not in accordance with current tax regulations, and necessary adjustments should be made for CIT purposes
A34: 1.2 | B34: Check relevant supporting documents (on a sampling basis) whether the Company's sales is recognised in accordance with
B35: current CIT regulations
B36: - Sales of goods: Check sales contracts, purchase orders, invoices, delivery note | G36: o | H36: o
B37: - Provision of services: Check service contracts, invoices, notes of service completion | G37: o | H37: o
A40: 1.3 | B40: Discuss with the Company's management and review its CIT finalisation return and relevant adjustments of the | G40: o | H40: o
B41: previous year to determine whether any sales of the pervious year was decreased and will be included in the current
B42: year for CIT purposes. If YES, make the relevant incremental adjustment to the Company's taxable revenue of the
B43: current year for CIT purposes
A46: 1.4 | B46: Obtain the VAT declaration to sum up with the total revenue declared therein to determine
B47: - If the revenue on FS is higher than those of VAT declaration, please note the risk of under-declared VAT | G47: o | H47: o
B48: - If the revenue on FS is lower than those of VAT declaration, please clarify to make incremental adjustments (if any) | G48: o | H48: o
A51: 1.5 | B51: Review the Company's sales deduction, and relevant supporting documents to determine whether they are deductible for CIT purposes
B52: - Commercial discount: check sales contracts, discount policies, VAT invoices | G52: o | H52: o
B53: - Sales returns: check minutes of sales return, VAT invoices, import documents (for exported goods only) | G53: o | H53: o
B54: If NOT, sales deductions will not be deductible and be added back to the revenue for CIT purposes
B55: [Please include further comments for manager's attention and decision]
A57: 2. Proposed adjustment
B59: No. | C59: Description of adjustment | D59: Amount | E59: Ref. | F59: Note
B61: 1 | C61: Under-declared taxable revenue
B62: 2 | C62: Non-deductible sales deductions
B63: 3 | C63: Other adjustment (please specify)
C65: Total
A67: 3. Proposed action
A68: The total adjustment value presented in this worksheet must be posted to Item B2 of the CIT return.

Sheet B3
A1: ABCD | F1: WP-B3
A3: Company name: | E3: Name | F3: Date
A4: Period: | D4: Prepared by:
D5: Reviewed by:
A7: Item B3 - Expenses relevant to decremental adjustment of taxable revenue
A14: 1. Approach guidance | E14: Completed | F14: Reviewed
A16: 1.1 | B16: Review and determine if the Company's revenue of current year is decreased and included in Item B9 | E16: o | F16: o
B17: If YES, request the Company to quantify expenses which are relevant to its decreased revenue
B18: and add back to the Company's taxable income of current year for CIT purposes.
B19: [Please include further comments for manager's attention and decision]
A21: 2. Proposed adjustment
B23: No. | C23: Description of adjustment | D23: Amount | E23: Ref. | F23: Note
B25: 1 | C25: Expenses related to decremental revenue of this year
C27: Total
A29: 3. Proposed action
B30: The total adjustment value presented in this worksheet must be posted to Item B3 of the CIT return.

Sheet B4.1
A1: ABCD | H1: WP-B4.1
A3: Company name: | G3: Name | H3: Date
A4: Period: | F4: Prepared by:
F5: Reviewed by:
A7: Item B4.1 - Non-deductible depreciation expenses
A25: 1. Approach guidance | G25: Completed | H25: Reviewed
A27: 1.1 | B27: Obtain the calculation of the Company's depreciation expenses of current year, and check if it is consistent with | G27: o | H27: o
B28: the total depreciation expense charged into the Company's P&L. If NOT, check the reason of the difference | G28: o | H28: o
B29: [Please include further comments for manager's attention and decision]
A31: 1.2 | B31: Randomly check if any of the Company's fixed assets are NOT used for "business" purposes. | G31: o | H31: o
B32: If NOT, add back non-deductible depreciation expense into the Company's taxable income for CIT purposes
B33: [Please include further comments for manager's attention and decision]
A35: 1.3 | B35: Randomly check if any of the Company’s fixed assets are NOT legally owned (e.g. supported by legitimate | G35: o | H35: o
B36: invoices, ownership certificate, etc.). If NOT, add back non-deductible depreciation expenses into the Company's
B37: taxable income for CIT purposes
B38: [Please include further comments for manager's attention and decision]
A40: 1.4 | B40: Randomly check if depreciation expenses are correctly calculated and charged into the P&L (i.e. correct useful | G40: o | H40: o
B41: life, depreciation date, etc.). If NOT, add back over-claimed depreciation expenses into Item B4, and include
B42: under-claimed depreciation expenses into Item B11
B43: [Please include further comments for manager's attention and decision]
A45: 1.5 | B45: Check if any of the Company's fixed assets are temporarily NOT is use. If YES, they meet the following conditions:
B46: - The interruption period must be less than 9 months in case of seasonal production | G46: o | H46: o
B47: - The interruption period must be less than 12 months in case of relocation, periodical repairment, or maintenance | G47: o | H47: o
B48: - Supporting documents evidencing reasons of such interruption are sufficiently maintained | G48: o | H48: o
B49: If NOT, depreciation expenses related to those fixed assets will not be deductible and added back to the Company's
B50: taxable income for CIT purposes
B51: [Please include further comments for manager's attention and decision]
A53: 1.6 | B53: Check if any of the Company's fixed assets are purchased and constructed using its loans. If YES, | G53: o | H53: o
B54: check if incurred loan interest has been capitalised into the historical costs of the related fixed assets until they
B55: are out in use. If NOT, make relevant adjustments on the Company's operating expenses and depreciation expenses
B56: [Please include further comments for manager's attention and decision]
A58: 1.7 | B58: Check if any of the Company's fixed assets were renovated, improved, or repaired during current year. If YES, | G58: o | H58: o
B59: check how the costs of renovation, improvement or repair is correctly claimed for CIT purposes:
B60: - Costs of major renovation or improvement must be capitalised into historical costs of related fixed assets | G60: o | H60: o
B61: - Costs of repair must be fully charged in operating expenses of current year | G61: o | H61: o
B62: [Please include further comments for manager's attention and decision]
A64: 1.8 | B64: Obtain and check if there is any temporary adjustment to the Company's depreciation expenses in previous year. | G64: o | H64: o
B65: If YES, check if those adjustments should be claimed in current year for CIT purposes. If YES, include it
B66: into Item B11 for CIT purposes
B67: [Please include further comments for manager's attention and decision]
...

Sheet B4.2
A1: ABCD | H1: WP-B4.2
A3: Client name : | G3: Name | H3: Date
A4: Period end: | F4: Prepared by:
F5: Reviewed by:
A7: WP B4.2 - Non-deductible cost of raw materials, materials, fuel, power, or goods
A22: 1. Approach guidance: | G22: Completed | H22: Reviewed
A24: 1.1 | B24: Check if the Client has notified the "reasonable" consumption levels of its raw materials, fuel, power and goods | G24: o | H24: o
B25: with local tax authorities within statutory deadline. Obtain a copy of such notification for comparison
B26: [Please include further comments for manager's attention and decision]
A28: 1.2 | B28: If the answer to Item 1.1 above is YES, check if the Client's cost of raw materials, fuel, power, goods exceed | G28: o | H28: o
B29: the notified "reasonable" consumption level. If yes, add the non-deductible exceeding value into the Client's
B30: taxable income for CIT purposes
A32: 1.3 | B32: Check if the Client has recorded cost of goods which are destroyed due to their expiry into P/L. | G32: o | H32: o
A34: 1.4 | B34: If the answer to Item 1.3 above is YES, check if the Client maintains proper supporting documents for the claimed expenses | G34: o | H34: o
B35: If no, add the cost back to the Client's taxable income for CIT purposes
A37: 2. Proposed adjustment
F38: (Unit: VND)
A39: No. | B39: Description | C39: Value | E39: Non-deductible | F39: Notes
C40: Per notification | D40: Per books | E40: amount
A41: 1 | C41: 0 | D41: 0
A42: 2 | C42: 0 | D42: 0 | E42: =IF(D42>C42,D42-C42,0) -> 0
A43: 3 | C43: 0 | D43: 0 | E43: =IF(D43>C43,D43-C43,0) -> 0
A44: 4 | C44: 0 | D44: 0 | E44: =IF(D44>C44,D44-C44,0) -> 0
A45: 5 | C45: 0 | D45: 0 | E45: =IF(D45>C45,D45-C45,0) -> 0
A46: 6 | C46: 0 | D46: 0 | E46: =IF(D46>C46,D46-C46,0) -> 0
A47: 7 | C47: 0 | D47: 0 | E47: =IF(D47>C47,D47-C47,0) -> 0
A48: 8 | C48: 0 | D48: 0 | E48: =IF(D48>C48,D48-C48,0) -> 0
A49: 9 | C49: 0 | D49: 0 | E49: =IF(D49>C49,D49-C49,0) -> 0
A50: 10 | C50: 0 | D50: 0 | E50: =IF(D50>C50,D50-C50,0) -> 0
B51: Total | C51: =SUM(C41:C50) -> 0 | D51: =SUM(D41:D50) -> 0 | E51: =SUM(E41:E50) -> 0
A53: 3. Proposed action
A54: The above non-deductible costs of raw materials, fuel, power, and goods must be posted to Item B4 of the CIT return

Sheet B4.3
A1: ABCD | H1: WP-B4.3
A3: Client name: | G3: Name | H3: Date
A4: Period: | F4: Prepared by:
F5: Reviewed by:
A7: Item B4.3 - Non-deductible interest expenses
A26: 1. Approach guidance | G26: Completed | H26: Reviewed
A28: 1.1 | B28: Check if any of the Company's loans are obtained from individuals, and claim interest expenses on such loans. | G28: o | H28: o
B29: If YES, check if the applicable interest rate of such loans exceeds 1.5 times of the prime borrowing rate
B30: promulgated by SBV. If YES, add back non-deductible interest expenses which relates to the exceeding portion
B31: into the Company's taxable income for CIT purposes
B32: [Please include further comments for manager's attention and decision]
A34: 1.2 | B34: Check if the Company obtains any medium or long-term loans from offshore institution/individuals. If YES, | G34: o | H34: o
B35: check if such loans are registered with local SBV. If NOT, add back related interest expenses into
B36: the Company's taxable income for CIT purposes
B37: [Please include further comments for manager's attention and decision]
A39: 1.3 | B39: Check if the Company has fully contributed its capital in accordance with its capital contribution schedule | G39: o | H39: o
B40: registered with relevant licensing authorities. If NOT, add back interest expenses which correspond to the
B41: non-contributed capital amount into the Company's taxable income for CIT purposes
B42: [Please include further comments for manager's attention and decision]
A44: 1.4 | B44: Check and compare the value of loan agreements to the total balances of cash-in accounts | G44: o | H44: o
B45: and cash-at bank accounts as at the loan agreement date to assess whether the total amount equals to
B46: or exceeds the principal loan amount. If yes, quantify the interest expense of such loan agreement for note
B47: in the report. Please note that this is applicable to HCMC practice only.
B48: [Please include further comments for manager's attention and decision]
A50: 1.5 | B50: Check whether the Company has free-interest loans to other entities while it has loan agreements with interest charges during the tax year. | G50: o | H50: o
B51: If yes, the deemed interest income at the market rate should be taken into account for calculation of other income in WP-Other income or the interest of the loan
B52: [Please include further comments for manager's attention and decision]
A55: 2. Proposed adjustment
B57: No. | C57: Description of adjustment | D57: Amount | E57: Ref. | F57: Note
B59: 1 | C59: Non-deductible interest expenses related to loans obtained from individuals and its interest rate exceeds 1.5 times of the prime borrowing rate announced by SBV
B60: 2 | C60: Non-deductible interest expenses related to offshore loans which are not registered with SBV
B61: 3 | C61: Interest expenses related loans which correspond to the non-contributed charter capital
B62: 4 | C62: Other non-deductible interest expenses
C63: Total
A65: 3. Proposed action
A66: The total adjustment value presented in this worksheet must be posted to Item B4 of the CIT return.

Sheet B4.4
A1: ABCD | I1: WP-B4.4
A3: Company name: | H3: Name | I3: Date
A4: Period: | G4: Prepared by:
G5: Reviewed by:
A7: Item B4.4 - Expenses without legitimate invoices
A15: 1. Approach guidance | H15: Completed | I15: Reviewed
A17: 1.1 | B17: Discuss with the Company's tax accountant to assess his/her understanding on Vietnamese regulations | H17: o | I17: o
B18: on legitimacy of invoices and supporting documents for accounting and tax purposes
B19: [Please include further comments for manager's attention and decision]
A21: 1.2 | B21: Obtain the list of expenses which are not supported by legitimate invoices/documents and | H21: o | I21: o
B22: self-assessed by the Company (if available), and check if the list is prepared in accordance with the current regulations
A24: 1.3 | B24: Randomly check some of the Company's expense accounts to see if any of its expenses are NOT supported | H24: o | I24: o
B25: by legitimate invoices (if necessary)
B26: [Please include further comments for manager's attention and decision]
A29: 2. Proposed adjustment
B31: No. | C31: Description of adjustment | E31: Amount | F31: Ref. | G31: Note
B33: 1 | C33: Expenses without legitimate invoices per self-assessment
B34: 2 | C34: Expenses without legitimate invoices per KPMG's sample check
B35: 3 | C35: Other adjustment (please specify)
C36: Total
A38: 3. Proposed action
A39: The total adjustment value presented in this worksheet must be posted to Item B4 of the CIT return.

Sheet B4.5
A1: ABCD | H1: WP-B4.5
A3: Company name: | G3: Name | H3: Date
A4: Period: | F4: Prepared by:
F5: Reviewed by:
A7: Item B4.5 - Collection of penalties
A18: 1. Approach guidance | G18: Completed | H18: Reviewed
A20: 1.1 | B20: Check if the Company claims any penalties due to administrative violations in accounting, tax, etc. | G20: o | H20: o
B21: If YES, add such non-deductible penalties into the Company's taxable income for CIT purposes
B22: [Please include further comments for manager's attention and decision]
A24: 1.2 | B24: Obtain and check minutes of tax audits and decision on collection of back taxes during | G24: o | H24: o
B25: the year, and whether those amounts were claimed for CIT purposes. If YES, seek final decision from
B26: the engagement manager on relevant adjustments of the back taxes for CIT purposes
B27: [Please include further comments for manager's attention and decision]
A30: 2. Proposed adjustment
B32: No. | C32: Description of adjustment | D32: Amount | E32: Source | F32: Notes
B34: 1 | C34: Non-deductible administrative penalties | D34: 0
B35: 2 | C35: Non-deductible back taxes | D35: 0
B36: 3 | C36: Non-deductible tax collection
C37: Total | D37: =SUM(D34:D35) -> 0
A39: 3. Proposed action
A40: The total adjustment value presented in this worksheet must be posted to Item B4 of the CIT return.

Sheet B4.6
A1: ABCD | H1: WP-B4.6
A3: Company name: | G3: Name | H3: Date
A4: Period: | F4: Prepared by:
F5: Reviewed by:
A7: Item B4.6- Non-business expenses
A25: 1. Approach guidance | G25: Completed | H25: Reviewed
A27: 1.1 | B27: Discuss with the Company's tax accountant to assess his/her understanding on Vietnamese regulations | G27: o | H27: o
B28: on relevance of expenses for CIT purposes
B29: [Please include further comments for manager's attention and decision]
A31: 1.2 | B31: Obtain the list of non-business expenses which are self-assessed by the Company (if available) and check if it | G31: o | H31: o
B32: is in accordance with current CIT regulations.
B33: [Please include further comments for manager's attention and decision]
A35: 1.3 | B35: Randomly check some of the Company's expense accounts to see if any of its expenses are NOT relevant | G35: o | H35: o
B36: to its registered business activities (if necessary)
B37: [Please include further comments for manager's attention and decision]
A39: 2. Proposed adjustment
B41: No. | C41: Description of adjustment | D41: Amount | E41: Source | F41: Notes
B43: 1 | C43: Staff welfare | D43: 0
B44: 2 | C44: Benefits provided to staff's dependants | D44: 0
B45: 3 | C45: Gifts | D45: 0
B46: 4 | C46: Donation | D46: 0
B47: 5 | C47: Others | D47: 0
C49: Total | D49: =SUM(D43:D47) -> 0
A51: 3. Proposed action
A52: The total adjustment value presented in this worksheet must be posted to Item B4 of the CIT return.

Sheet B4.7
A1: ABCD | F1: WP-B4.7
A3: Company name: | E3: Name | F3: Date
A4: Period: | D4: Prepared by:
D5: Reviewed by:
A7: Item B4.7 - Employment related costs
A26: 1. Approach guidance | E26: Completed | F26: Reviewed
A28: 1.1 | B28: Obtain samples of the Company's payrolls (at least, 3 months per year) to understand its remuneration structure | E28: o | F28: o
B29: [Please include further comments for manager's attention and decision]
A31: 1.2 | B31: Obtain the Company's collective labour agreement, and samples of employment contracts (2 samples for each | E31: o | F31: o
B32: department, and check if any of employment items is not clearly stated in either the collective labour agreement
B33: or the employment contract. If YES, such employment expenses will not be deductible for CIT purposes
B34: [Please include further comments for manager's attention and decision]
A36: 1.3 | B36: Select at least two (2) local staff of each department, and 20% of the total number of the Company's expatriate | E36: o | F36: o
B37: employees and vouch their remuneration items (i.e. type, amount, etc.) to the above supporting documents
B38: (e.g. labour contracts, collective labour agreement, internal labour rules, internal decision, payment receipts, etc.)
B39: If NOT, such employment expenses will not be deductible for CIT purposes
A41: 2. Proposed adjustment
B43: No. | C43: Description of adjustment | D43: Amount | E43: Source | F43: Notes
B45: 1 | C45: Employment expenses without legitimate supporting documents
B46: 2 | C46: Salaries/ wages, and/or compensation paid to entity's owner or founding members
B47: 3 | C47: Others
C49: Total
A51: 3. Proposed action
A52: The total adjustment value presented in this worksheet must be posted to Item B4 of the CIT return.

Sheet B4.8
A1: ABCD | F1: WP-B4.8
A3: Company name: | E3: Name | F3: Date
A4: Period: | D4: Prepared by:
D5: Reviewed by:
A7: Item B4.8 - Accruals
A20: 1. Approach guidance | E20: Completed | F20: Reviewed
A23: 1.1 | B23: Interview the client to understand their accounting record relating to accruals
B24: [Please provide details explanation]
A26: 1.2 | B26: Obtain the Company's audited FS to determine its accrual balance at year-end | E26: o | F26: o
B27: (Hints: Please note that some accruals may be recorded under payables
B28: Therefore, we should obtain clarification from Company's management and/or review relevant documents to get
B29: a full understanding of the Company's accounting treatment for its accruals)
B30: [Please include further comments for manager's attention and decision]
A32: 1.3 | B32: Obtain the Company's CIT return of previous year and determine if any of its accruals was added back | E32: o | F32: o
B33: to its taxable income of previous year. If YES, check if those accruals were actually paid in curernt year,
B34: are relevant to the Company's registered business activities, and supported by legitimate invoices/documents.
B35: If YES, they must be included into the Company's deductible expenses of current year for CIT purposes
B36: [Please include further comments for manager's attention and decision]
A38: 2. Proposed adjustment
B40: No. | C40: Description of adjustment | D40: Amount | E40: Source | F40: Notes
B42: 1 | C42: Non-deductible accruals | D42: 0
C44: Total | D44: =SUM(D42) -> 0
A46: 3. Proposed action
A47: The total adjustment value presented in this worksheet will be posted to Item B4 of the CIT return.

Sheet B4.9
A1: ABCD | F1: WP-B4.9
A3: Company name : | E3: Name | F3: Date
A4: Period end: | D4: Prepared by:
D5: Reviewed by:
A7: Item B4.9 - Non-deductible provisional expenses
A18: 1. Summary of non-deductible provisional expenses
B20: No. | C20: Description of adjustment | D20: Amount | E20: Ref. | F20: Notes
B21: 1 | C21: Non-deductible provision for severance allowance | D21: =B4.9.1!D26 -> 0 | E21: B4.9.1
B22: 2 | C22: Non-deductible provision for obsolete inventory | D22: =B4.9.2!D57 -> 0 | E22: B4.9.2
B23: 3 | C23: Non-deductible provision for loss from financial investment | D23: =B4.9.3!C83 -> 0 | E23: B4.9.3
B24: 4 | C24: Non-deductible provision for bad debts | D24: =B4.9.4!C53 | E24: B4.9.4
B25: 5 | C25: Non-deductible provision for warranties | D25: =B4.9.5!C44 | E25: B4.9.5
C26: Total | D26: =SUM(D21:D25) -> 0
A28: 3. Proposed action
A29: The total adjustment value presented in this worksheet will be posted to Item B4 of the CIT return.

Sheet B4.9.1
A1: ABCD | I1: WP-B4.9.1
A3: Company name : | H3: Name | I3: Date
A4: Period end: | G4: Prepared by:
G5: Reviewed by:
A7: Item B4.9.1 - Non-deductible provision for severance allowance
A13: 1. Approach guidance | H13: Completed | I13: Reviewed
A15: 1.1 | B15: Check with the Company's tax accountant on whether the Company makes provision for severance allowance | H15: o | I15: o
B16: [Please include further comments for manager's attention and decision]
A18: 1.2 | B18: Check the actual payment for severance allowance made by the Company during the year (if any) | H18: o | I18: o
B19: If the payment is not paid in accordance with current regulations, the amount is non deductible expense
A21: 2. Proposed adjustment
B23: No. | C23: Description | D23: Amount | E23: Source | F23: Notes
B24: 1 | C24: Provision for severance allowance made during the year | D24: 0 | E24: P&L, GL
B25: 2 | C25: Payment for severance allowance not in accordance with current regulations | E25: P&L, GL
C26: Total | D26: =SUM(D24:D25) -> 0
A28: 3. Proposed action
A29: The non-deductible provision for severance allowance must be posted to WP-B4.9
A30: The provision for severan allowance which was added back to the Company's taxable income of previous year, but actually realised in current year
A31: must be posted to WP-B11

Sheet B4.9.2
A1: ABCD | F1: WP-B4.9.2
A3: Company name : | E3: Name | F3: Date
A4: Period end: | D4: Prepared by:
D5: Reviewed by:
A7: Item B4.9.2 - Non-deductible provision for obsolete inventory
A26: 1. Approach guidance | E26: Completed | F26: Reviewed
A28: 1.1 | B28: Discuss with the Company to understand its provision for obsolete inventory and relevant accounting policies | E28: o | F28: o
B29: applied when making such provision
B30: [Please include further comments for manager's attention and decision]
A32: 1.2 | B32: Check if the Company's provision for obsolete inventory is supported by legitimate supporting documents provided | E32: o | F32: o
B33: by Circular 228, specifically including:
B35: - Decision on establishment of a committee in charge of making provision for obsolete inventory, | E35: o | F35: o
B37: - Purchase contracts and invoices justifying the Company's legal ownership on the inventory | E37: o | F37: o
B39: - Relevant documents justifying the realisable value of the Company's inventory) | E39: o | F39: o
A41: 1.3 | B41: Check if the Company's provision for obsolete inventory charged in current year is made in accordance with | E41: o | F41: o
B42: Circular 228. If NOT, add back non-deductibe provision into the Company's taxable income for CIT purposes
B43: (complete WP-B4.9.2a)
A45: 1.4 | B45: Check if any of the Company's provision for obsolete inventory which was added back to its taxable income | E45: o | F45: o
B46: of previous year for CIT purposes. If YES, determine and make relevant adjustment in the Company's deductible
B47: expenses of current year when the provision is actually realised in current year
B48: [Please include further comments for manager's attention and decision]
A50: 2. Proposed adjustment
B52: No. | C52: Description | D52: Amount | E52: Source | F52: Notes
B53: 1 | C53: Ending balance of provision for obsolete inventory | E53: FS
B54: 2 | C54: Allowable provision for obsolete inventory | E54: WP-B4.9.2 (a)
B55: 3 | C55: Compare (1) against (2):
B56: 4 | C56: If (2) > or = (1), no adjustment is required for CIT purposes
B57: 5 | C57: If (2) < (1), the difference will be compared with provision for obsolete inventory added back to taxable income in previous fiscal years
A60: 3. Proposed action
A61: The non-deductible provision for obsolete inventory must be posted to B4.9

Sheet B4.9.2a
A1: ABCD | I1: WP-B4.9.2a
A3: Client name : | H3: Name | I3: Date
A4: Period end: | G4: Prepared by:
G5: Reviewed by:
A7: CALCULATION OF ALLOWABLE PROVISION FOR OBSOLETE INVENTORY
A9: No. | B9: Description | C9: Quantity | D9: Historical | E9: Estimated | F9: Estimated | G9: Estimated | H9: NRV | I9: Allowable
B10: of inventory | D10: cost | E10: selling price | F10: production cost | G10: selling cost | I10: provision
A11: [1] | B11: [2] | C11: [3] | D11: [4] | E11: [5] | F11: [6] | G11: [7] | H11: [8]=[5]-[6]-[7] | I11: [9]=[3]*([4]-[8])
A13: 1 | H13: =E13-F13-G13 -> 0 | I13: =C13*(D13-H13) -> 0
A14: 2 | H14: =E14-F14-G14 -> 0 | I14: =C14*(D14-H14) -> 0
A15: 3 | H15: =E15-F15-G15 -> 0 | I15: =C15*(D15-H15) -> 0
A16: 4 | H16: =E16-F16-G16 -> 0 | I16: =C16*(D16-H16) -> 0
A17: 5 | H17: =E17-F17-G17 -> 0 | I17: =C17*(D17-H17) -> 0
B19: Total

Sheet B4.9.3
A1: ABCD | H1: WP-B4.9.3
A3: Company name : | G3: Name | H3: Date
A4: Period end: | F4: Prepared by:
F5: Reviewed by:
A7: Item B4.9.3 - Non-deductible provision for devaluation of financial investments
A27: 1. Approach guidance | G27: Completed | H27: Reviewed
A29: 1.1 | B29: Discuss with the Company to understand about its provision for devaluation of financial investments and relevant | G29: o | H29: o
B30: accounting policies applied when make such provisions
B31: [Please include further comments for manager's attention and decision]
A33: 1.2 | B33: Check if the Company's provision for devaluation of financial investments satisfy the conditions provided in Circular 228, | G33: o | H33: o
B34: specifically including:
B35: [Please include further comments for manager's attention and decision]
B36: - Securities: whether they are legally invested by the Company in accordance with current regulations, and freely traded in | G36: o | H36: o
B37: stock markets, and their market prices are less than their historical costs
B39: - Long-term financial investments: whether ther are made in accordance with current regulations, and the invested entity | G39: o | H39: o
B40: is in loss position (please note that if the invested entity incurs losses which have been forecasted in its business plan prior to
B41: investment, provision for devaluation of long-term financial investments is not allowed).
A43: 1.3 | B43: Check if the Company's provision for devaluation of financial investments is supported by legitimate supporting documents | G43: o | H43: o
B44: provided in Circular 228, specifically including:
B46: - Decision on establishment of a committee in charge of making provision for devaluation of financial investments | G46: o | H46: o
B48: - Supporting documents in case of securities: certificates of investment in securities, purchase contracts, securities | G48: o | H48: o
B49: ownership certificates, securities valuation statement, etc.
B51: - Additional supporting documents in case of long-term financial investment: certificates of capital contribution, | G51: o | H51: o
B52: audited financial statements of the invested entity, etc.
A54: 1.4 | B54: Review the detailed calculation of the Company's provision for devaluation of financial investments which are charged in | G54: o | H54: o
B55: its P&L of current year and check if it i made in accordance with Circular 228. If NOT, add non-deductibe provision
B56: into the Company's taxable income for CIT purposes (complete WP-B4.9.3a)
A58: 1.5 | B58: Check if any of the Company's provision for devaluation of financial investments which was added back to its taxable income | G58: o | H58: o
B59: of previous year for CIT purposes. If YES, determine and make relevant adjustment in the Company's deductible expenses
B60: of current year when the provision is actually realised in current year
B61: [Please include further comments for manager's attention and decision]
A63: 2. Proposed adjustment
A65: 2.1 Non-deductible provision for devaluation of investment in securities
A67: No. | B67: Description | C67: Amount | D67: Source | E67: Notes
A68: 1 | B68: Ending balance of provision for devaluation of investment in securities | D68: B/S
A69: 2 | B69: Allowable provision for devaluation of investment in securities | D69: WP-B4.9.3a
A70: 3 | B70: Compare (1) against (2):
A71: a | B71: If (2) > or = (1), no adjustment is required for CIT purposes
A72: b | B72: If (2) < (1), the difference will be added back to the Company's taxable income for CIT purposes
A74: 2.2 Non-deductible provisions for devaluation of long-term financial investment
...

Sheet B4.9.3a
A1: ABCD | F1: WP-B4.9.3a
A3: Client name : | E3: Name | F3: Date
A4: Period end: | D4: Prepared by:
D5: Reviewed by:
A8: CALCULATION OF ALLOWABLE PROVISION
A9: FOR DEVALUATION OF FINANCIAL INVESTMENTS
A11: 1. Investment in securities
A13: Approach guidance:
A14: - Obtain the Client's list of investment in securities, and check the legal ownership of the
A15: Client's securities and whether the securities are freely traded in the market.
A16: - Verify the historical cost and market price of the Client's securities.
A17: - Perform the calculation of allowable provision for devaluation of investment in securities.
A19: No. | B19: Description | C19: Quantity | D19: Historical | E19: Market | F19: Allowable
B20: of securities | D20: cost | E20: price | F20: provision
A21: [1] | B21: [2] | C21: [3] | D21: [4] | E21: [5] | F21: [6]=[3]*([4]-(5)]
A23: 1 | F23: =C23*(D23-E23) -> 0
A24: 2 | F24: =C24*(D24-E24) -> 0
A25: 3 | F25: =C25*(D25-E25) -> 0
A26: 4 | F26: =C26*(D26-E26) -> 0
A27: 5 | F27: =C27*(D27-E27) -> 0
B29: Total
A31: 2. Long-term financial investments
A33: Approach guidance:
A34: - Obtain the Client's list of long-term financial investments, and check the legal ownership
A35: of the Client's long-term financial investments, and whether the invested entity is in loss
A36: position (except for losses which have been pre-forecasted prior to investment)
A37: - Verify the actual capital contribution of all shareholders, and the actual value of the contributed
A38: capital as at year end
A39: - Perform the calculation of allowable provision for devaluation of long-term financial
A40: investments.
A42: No. | B42: Description of | C42: Actual | D42: Actual | E42: Capital contributed | F42: Allowable
B43: financial investment | C43: capital contribution | D43: capital value | E43: by the Client | F43: provision
A44: [1] | B44: [2] | C44: [3] | D44: [4] | E44: [5] | F44: [6]=([3]-[4])*[5]/[3]
A46: 1 | F46: =(C46-D46)*E46/C46 -> #DIV/0!
A47: 2 | F47: =(C47-D47)*E47/C47 -> #DIV/0!
A48: 3 | F48: =(C48-D48)*E48/C48 -> #DIV/0!
A49: 4 | F49: =(C49-D49)*E49/C49 -> #DIV/0!
A50: 5 | F50: =(C50-D50)*E50/C50 -> #DIV/0!
B52: Total

Sheet B4.9.4
A1: ABCD | G1: WP-B4.9.4
A4: Company name : | F4: Name | G4: Date
A5: Period end: | E5: Prepared by:
E6: Reviewed by:
A8: Item B4.9.4 - Non-deductible provision for doubtful debts
A22: 1. Approach guidance | F22: Completed | G22: Reviewed
A24: 1.1 | B24: Discuss with the Company's tax accountant to understand about its provision for doubtful debts and relevant accounting | F24: o | G24: o
B25: policies applied when making such provisions
B26: [Please include further comments for manager's attention and decision]
A28: 1.2 | B28: Check if the Company's provision for doubtful debt satisfy the conditions provided in Circular 228, | F28: o | G28: o
B30: - Debts becomes doubtful or the debtor declares bankruptcy, dissolves, disappears, runs away, is subject to prosecution | F30: o | G30: o
B31: or detention, or dies, etc.)
A33: 1.3 | B33: Check if the Company's provision for doubtful debt is supported by legitimate supporting documents provided in | F33: o | G33: o
B34: Circular 228 (e.g. sales contract, debt confirmation issued by the debtors, economic contracts
B35: loan contract, other debt confirmation, etc.)
A37: 1.4 | B37: Check if the detailed calculation of the Company's provision for doubtful debt which are charged in its P&L of current | F37: o | G37: o
B38: year is made in accordance with Circular 228. If NOT, add non-deductible provision into the Company's taxable income
B39: of current year for CIT purposes (complete WP-B4.9.4a)
A41: 1.5 | B41: Check if any of the Company's provision for doubtful debt which was added back to its taxable income | F41: o | G41: o
B42: of previous year for CIT purposes. If YES, determine and make relevant adjustment in the Company's deductible expenses
B43: of current year when the provision is actually realised in current year
B44: [Please include further comments for manager's attention and decision]
A46: 2. Proposed adjustment
A48: No. | B48: Description | C48: Amount | D48: Source | E48: Notes
A49: 1 | B49: Ending balance of provision for doubtful debt | D49: B/S
A50: 2 | B50: Allowable provision for doubtful debt | D50: WP-B4.9.4a
A51: 3 | B51: Compare (1) against (2):
A52: a | B52: If (2) > or = (1), no adjustment is required for CIT purposes
A53: b | B53: If (2) < (1), the difference will be added back to the Company's taxable income for CIT purposes | C53: =IF(C50<C49,C49-C50,"")
A55: 3. Proposed action
A56: The above non-deductible provision for doubtful debt must be posted to B4.9

Sheet B4.9.4a
A1: ABCD | E1: WP-B4.9.4a
A3: Client name : | D3: Name | E3: Date
A4: Period end: | C4: Prepared by:
C5: Reviewed by:
A8: CALCULATION OF ALLOWABLE PROVISION
A9: FOR DOUBTFUL DEBT
A11: No. | B11: Description | C11: Total value | D11: Capped provision | E11: Allowable
B12: of debt | C12: of overdue debt | D12: percentage | E12: provision
A13: [1] | B13: [2] | C13: [3] | D13: [4] | E13: [5]=[3]*[4]
A15: 1 | B15: Debts with the aging period of 6 months or above, but less than 1 year | D15: 0.3 | E15: =C15*D15 -> 0
A16: 2 | B16: Debts with the aging period of 1 year or above, but less than 2 years | D16: 0.5 | E16: =C16*D16 -> 0
A17: 3 | B17: Debts with the aging period of 2 years or above, but less than 3 years | D17: 0.7 | E17: =C17*D17 -> 0
A18: 4 | B18: Debts with the aging period of 3 years or above | D18: 1 | E18: =C18*D18 -> 0
B20: Total | E20: =SUM(E15:E19) -> 0

Sheet B4.9.5
A1: ABCD | F1: WP-B4.9.5
A4: Company name : | E4: Name | F4: Date
A5: Period end: | D5: Prepared by:
D6: Reviewed by:
A8: Item B4.9.5 - Non-deductible provision for warranty
A21: 1. Approach guidance | F21: Completed | G21: Reviewed
A23: 1.1 | B23: Discuss with the Company to understand about its provision for warranty and relevant accounting policies | F23: o | G23: o
B24: [Please include further comments for manager's attention and decision]
A26: 1.2 | B26: Check if the Company's provision for warranty is supported by legitimate supporting documents | F26: o | G26: o
B27: (sales contracts, construction contracts, etc.)
A29: 1.3 | B29: Check if the Company's provision for warranty meet the conditions set in Circular 228 (i.e. the provision | F29: o | G29: o
B30: relates to goods and/or construction projects which are sold and/or delivered in current year, and guaranteed in related
B31: sales contracts, etc.)
A33: 1.4 | B33: Review the detailed calculation of the Company's provision for warranty which are charged in | F33: o | G33: o
B34: its P&L of current year and check if it is made in accordance with Circular 228. If NOT, add non-deductible provision
B35: for warranty into the Company's taxable income for CIT purposes (complete WP-B4.9.5a)
A37: 2. Proposed adjustment
A39: No. | B39: Description | C39: Amount | D39: Source | E39: Notes
A40: 1 | B40: Provision for warranty made and charged in the current year | D40: P/L
A41: 2 | B41: Allowable provision for warranty | C41: =B4.9.5a!F21 -> 0
A42: 3 | B42: Compare (1) against (2):
A43: a | B43: If (2) > or = (1), no adjustment is required for CIT purposes | C43: =IF(C41=C40,"NO ADJUSTMENT","") -> NO ADJUSTMENT
A44: b | B44: If (2) < (1), the difference will be added back to the Company's taxable income for CIT purposes | C44: =IF(C41<C40,C40-C41,"")
A46: 3. Proposed action
A47: The above non-deductible provision for warranty must be posted to B4.9

Sheet B4.9.5a
A1: ABCD | F1: WP-B4.9.5a
A3: Client name : | E3: Name | F3: Date
A4: Period end: | D4: Prepared by:
D5: Reviewed by:
A8: CALCULATION OF ALLOWABLE PROVISION
A9: FOR WARRANTY
A11: No. | B11: Description | C11: Total value | D11: Warranty % | E11: Applicable | F11: Allowable
B12: of warranty | C12: of sales revenue | D12: per contract | E12: warranty percentage | F12: provision
A13: [1] | B13: [2] | C13: [3] | D13: [4] | E13: [5] | F13: [6]=[3]*[5]
A15: 1 | E15: =IF(D15<=5%,D15,5%) -> 0 | F15: =C15*E15 -> 0
A16: 2 | E16: =IF(D16<=5%,D16,5%) -> 0 | F16: =C16*E16 -> 0
A17: 3 | E17: =IF(D17<=5%,D17,5%) -> 0 | F17: =C17*E17 -> 0
A18: 4 | E18: =IF(D18<=5%,D18,5%) -> 0 | F18: =C18*E18 -> 0
A19: 5 | E19: =IF(D19<=5%,D19,5%) -> 0 | F19: =C19*E19 -> 0
B21: Total | F21: =SUM(F15:F20) -> 0

Sheet B4.10
A1: ABCD | H1: WP-B4.10
A3: Company name: | G3: Name | H3: Date
A4: Period: | F4: Prepared by:
F5: Reviewed by:
A7: Item B4.10 - Management fees
A18: 1. Approach guidance | G18: Completed | H18: Reviewed
A20: 1.1 | B20: Check if the Company claimed any management expenses allocated by its parent company. If YES, check if | G20: o | H20: o
B21: the Company is qualified as a PE of its parent company. If NOT, the management expenses allocated will not be
B22: deductible and added back to the Company's taxable income for CIT purposes
B23: (Hints: please refer to the definition of a PE in Circular 123 for further information).
B24: [Please include further comments for manager's attention and decision]
A26: 1.2 | B26: If the Company is a PE of its parent company, check if the management expenses allocated | G26: o | H26: o
B27: by the parent company has been paid by the Company. If NOT, check if such accrued expenses have been
B28: added back to the Company's taxable income under Item B4.8. If YES, no further adjustment is required
A30: 1.3 | B30: If the answer to Point 1.2 is YES, check if the management expenses are based on "cost allocation" or | G30: o | H30: o
B31: supported by relevant supporting documents
B32: (e.g. group policies or agreements on actual management services rendered, debit notes, etc.)
A34: 1.4 | B34: If the answer to Point 1.3 is YES, check if the management expenses are correctly calculated and
B35: allocated to the Company (perform the calculation at Point 2 below)
A37: 1.5 | B37: Check if the management expenses are valid and comply with FCT withholding on payment? | G37: o | H37: o
A39: 2. Proposed adjustment
B41: No. | C41: Description of adjustment | D41: Amount | E41: Source | G41: Notes
B43: 1 | C43: Total management expenses allocated by the offshore parent company and charged to the Company's P/L | E43: The Company's audited P/L, group policies or agreement on allocation of management expenses, and debit notes, etc. | G43: [a]
B44: 2 | C44: Total taxable turnover of the Company | D44: 0 | E44: The Company's audited P/L after taking into account of tax adjustments (if any) | G44: [b]
B45: 3 | C45: Total turnover of the offshore parent company (including the taxable turnover of the Company in Vietnam) | D45: 0 | E45: The parent company’s audited FS (normally consolidated FS) | G45: [c]
B46: 4 | C46: Total management expenses incurred by the offshore parent company during the year | D46: 0 | E46: The parent company’s audited FS (normally consolidated FS) | G46: [d]
B47: 5 | C47: Deductible management expenses allocated by the parent company | D47: 0 | G47: [e]=[d]*[b]/[c]
B48: 6 | C48: Non-deductible management expenses allocated by the overseas entity | D48: 0 | G48: [f]=[a]-[e]
B49: 7 | C49: Non-deductible contribution to management fund of the corporate's higher authorities | E49: The Company's audited P/L, group policies or agreement oncontribution, and debit notes, etc.
A52: 3. Proposed action
A53: The total adjustment value presented in this worksheet will be posted to Item B4 of the CIT return.

Sheet B4.11
A1: ABCD | F1: WP-B4.11
A3: Company name: | E3: Name | F3: Date
A4: Period: | D4: Prepared by:
D5: Reviewed by:
A7: Item B4.11- Unrealised foreign exchange loss
A17: 1. Approach guidance | E17: Completed | F17: Reviewed
A19: 1.1 | B19: Obtain the list of the Company's unrealised foreign exchange losses which was charged into its P&L of | E19: o | F19: o
B20: current year and broken down in types. Check if any of the unrealised foreign exchange loss is incurred
B21: due to revaluation of accounts other than payable accounts. If YES, add them back to the Company's
B22: taxable income for CIT purposes
A24: 1.2 | B24: Discuss with the Company on whether there is any unrealised foreign exchange losses of payable accounts | E24: o | F24: o
B25: relating to construction of fixed assets which has not completed or used for the Company's business activities.
B26: If YES, please quantify the expense and add it back to the Company's taxable income for CIT purposes.
A29: 2. Proposed adjustment
B31: No. | C31: Description of adjustment | D31: Amount | E31: Source | F31: Notes
B33: 1 | C33: Unrealised foreign exchange losses due to revaluation of accounts (other than payable accounts) denominated in foreign currency | D33: 0
B34: 2 | C34: Unrealised foreign exchange losses due to revaluation of payable accounts which are related to construction of unused fixed assets | D34: 0
C36: Total | D36: =SUM(D33:D34) -> 0
A38: 3. Proposed action
A39: The total adjustment value presented in this worksheet will be posted to Item B4 of the CIT return.

Sheet B4.12
A1: ABCD | F1: WP-B4.10
A3: Company name: | E3: Name | F3: Date
A4: Period: | D4: Prepared by:
D5: Reviewed by:
A7: Item B4.12 - Advertisement and promotion (A&P) expenses
A25: 1. Approach guidance | E25: Completed | F25: Reviewed
A27: 1.1 | B27: Obtain a list of the Company's A&P expenses and randomly check if they are relevant to the Company's | E27: o | F27: o
B28: registered business activities, and supported by legitimates invoices and supporting documents
B29: (e.g. contracts, notification of promotion programs to local trade authorities, etc.)
B30: [Please include further comments for manager's attention and decision]
A32: 1.2 | B32: Re-classify the Company's A&P expenses into various categories (i.e. fully-deductible A&P expenses, and
B33: A&P expenses subject to statutory cap)
B34: [Please include further comments for manager's attention and decision]
A36: 1.3 | B36: Calculate the Company's capped A&P expenses, and compare it against the Company's A&P expenses | E36: o | F36: o
B37: which are subject to the above cap, and add back the exceeding value into the Company's taxable
B38: income for CIT purposes (perform the calculation at WPB4.10.1)
A40: 2. Proposed adjustment
B42: No. | C42: Description of adjustment | D42: Amount | E42: Source | F42: Notes
B44: 1 | C44: Non-deductible A&P expenses | D44: 0
C46: Total | D46: =SUM(D44) -> 0
A48: 3. Proposed action
A49: The total adjustment value presented in this worksheet will be posted to Item B4 of the CIT return.

Sheet B4.12.1
A1: ABCD | F1: WP-B4.12.1
A3: Company name: | E3: Name | F3: Date
A4: Period: | D4: Prepared by:
D5: Reviewed by:
A7: CALCULATION OF NON-DEDUCTIBLE A&P EXPENSES
A9: Type of enterprise: | C9: % of cap | D9: Est. date | E9: Source
A10: o | B10: Newly established enterprises (< 3 years) | C10: 0.15 | D10: dd-mm-yy | E10: Invt certificate
A11: o | B11: Other enterprises | C11: 0.1 | D11: dd-mm-yy | E11: Invt certificate
A13: No. | B13: Description | C13: Amount | E13: Source | F13: Notes
C14: Manufacturing | D14: Trading
A15: A | B15: Total expenses per audited F/S | C15: =SUM(C16:C20) -> 0 | D15: =SUM(D16:D20) -> 0 | E15: FS | F15: a=sum of (A1 to A5)
A16: 1 | B16: Cost of good sold ("COGS") | C16: 0 | E16: FS
A17: 2 | B17: Selling expenses | C17: 0 | E17: FS
A18: 3 | B18: General and admin expenses | C18: 0 | E18: FS
A19: 4 | B19: Financial expenses | C19: 0 | E19: FS
A20: 5 | B20: Other expenses | C20: 0 | E20: FS
A21: B | B21: Add the following items | C21: =SUM(C22:C24) -> 0 | D21: =SUM(D22:D24) -> 0 | F21: b=sum of (B1 to B3)
A22: 1 | B22: Expenses related to incremental adjustments of taxable revenue | C22: 0 | E22: B10
A23: 2 | B23: Other incremental adjustments of deductible expenses in current year | C23: 0 | E23: B11
A24: 3 | B24: Accrued expenses excluded in previous year, but actually paid in current year | C24: 0 | E24: Note (1)
A25: C | B25: Subtract the following items | C25: =SUM(C26:C29) -> 0 | D25: =SUM(D26:D29) -> 0 | F25: c=sum of (C1 to C13)
A26: 1 | B26: COGS (if the Company is a trading company) | C26: 0 | E26: FS
A27: 2 | B27: Expenses related to decremental adjustments of taxable revenue | C27: 0 | E27: B3
A28: 3 | B28: Other decremental adjustments of deductible expenses in current year | C28: 0 | E28: B4 & B6
A29: 4 | B29: Legitimate A&P expenses subject to the statutory cap | C29: 0 | E29: B4.12.2
A30: D | B30: Base for calculating the capped A&P expense | C30: =C15+C21-C25 -> 0 | D30: =D15+D21-D25 -> 0 | F30: d=a+b-c
A31: E | B31: Capped A&P expenses | C31: =C30*0.1 -> 0 | D31: =D30*0.1 -> 0 | E31: Note (2) | F31: e=d*10% or 15%
A32: F | B32: Total A&P expenses subject to statutory cap (excluding non-legitimate A&P expenses) | C32: =C29 -> 0 | E32: WP-B4.12.2 | F32: f
A33: G | B33: Non-deductible A&P expenses | C33: =IF(C32>C31,C32-C31,0) -> 0 | D33: =IF(D32>D31,D32-D31,0) -> 0 | E33: Note (3) | F33: g=f-e (only if f > e)
A35: Notes
A36: (1) This figure is extracted from the Company's CIT finalisation return of the previous year.
A37: (2) The percentage of statutory cap is set at 10% by default. Please change it to 15% if the Company has been established for less than 3 years.
A38: (3) The non-deductible A&P amount presented in this worksheet will be posted to the worksheet B4.10.

Sheet B4.12.2
A1: ABCD | G1: WP-B4.12.2
A3: Client name: | F3: Name | G3: Date
A4: Period: | E4: Prepared by:
E5: Reviewed by:
A8: SUMMARY OF A&P EXPENSES SUBJECT TO STATUTORY CAP
A10: Account | B10: Ref | C10: Date | D10: Description | E10: Amount | G10: Notes
E11: Debit | F11: Credit
A17: Total | E17: 0 | F17: 0
A18: Net amount | E18: =E17-F17 -> 0

Sheet B5
A1: ABCD | I1: WP-B5
A3: Company name: | H3: Name | I3: Date
A4: Period: | G4: Prepared by:
G5: Reviewed by:
A7: Item B5 - Foreign tax payment
A16: 1. Approach guidance | H16: Completed | I16: Reviewed
A18: 1.1 | B18: Check if the Company received any offshore income during the year, If YES, obtain a breakdown of its | H18: o | I18: o
B19: offshore income, and check if the Company has made any offshore tax payments in relation to those offshore
B20: income, and claimed such foreign tax payments against its CIT payable in Vietnam
B21: [Please include further comments for manager's attention and decision]
A23: 1.2 | B23: If the answer to Item 1.1 above is YES, check if the Company's foreign tax payments has been | H23: o | I23: o
B24: included into the Company's taxable income for CIT purposes. If NOT, include it into the Company's taxable
B25: income for CIT purposes
B26: [Please include further comments for manager's attention and decision]
A28: 2. Proposed adjustment
B30: No. | C30: Description of adjustment | E30: Amount | F30: Ref. | G30: Note
B32: 1 | C32: Foreign tax payments
C34: Total
A36: 3. Proposed action
A37: The total adjustment value presented in this worksheet must be posted to Item B5 of the CIT return.

Sheet B6
A1: ABCD | F1: WP-B6
A3: Company name : | E3: Name | F3: Date
A4: Period end: | D4: Prepared by:
D5: Reviewed by:
A7: Item B6 - Other incremental adjustments of taxable income
A21: 1. Approach guidance | E21: Completed | F21: Reviewed
A23: 1.1 | B23: Obtain from relevant information and documents (e.g. calculation of provisions), and prepare relevant working | E23: o | F23: o
B24: papers, and include non-deductible expenses into this sheet.
A26: 2. Proposed adjustment
B28: No. | C28: Description of adjustment | D28: Amount | E28: Ref. | F28: Notes
B29: 1 | C29: Non-deductible staff uniform allowances | D29: 0 | E29: B6.1
B30: 2 | C30: Non-deductible per-diem allowances | D30: 0 | E30: B6.2
B31: 3 | C31: xxx | D31: 0
B32: 4 | C32: xxx | D32: 0
B33: 5 | C33: xxx | D33: 0
C34: Total | D34: =SUM(D29:D33) -> 0
A36: 3. Proposed action
A37: The total adjustment value presented in this worksheet will be posted to Item B6 of the CIT return.

Sheet B6.1
A1: ABCD | F1: WP-B6.1
A3: Client name : | E3: Name | F3: Date
A4: Period end: | D4: Prepared by:
D5: Reviewed by:
A7: WP B6.1 - Non-deductible staff uniform allowance
A12: 1. Approach guidance: | F12: Completed | G12: Reviewed
A14: 1.1 | B14: Check if the Company provides uniform allowance to staff. If YES, check if the uniform allowance is within statutory cap. | F14: o | G14: o
B15: If NOT, add back the excessive uniform allowance into the Company's taxable income for CIT purposes
B16: [Please include further comments for manager's attention and decision]
A18: 2. Proposed adjustment
A20: No. | B20: Description | C20: Amount | D20: Source | E20: Notes
A21: 1 | B21: Capped staff uniform allowance for CIT purposes | D21: A separate calculation sheet is needed
A22: 2 | B22: Total staff uniform allowance charged to P/L | C22: 0 | D22: P/L
A23: 3 | B23: Non-deductible staff uniform allowance for CIT purposes | C23: =IF(C22>C21,C22-C21,0) -> 0
A25: 3. Proposed action
A26: The non-deductible staff uniform allowance must be posted to Item B6 of the CIT return

Sheet B6.2
A1: ABCD | G1: WP-B6.2
A3: Company name : | F3: Name | G3: Date
A4: Period end: | E4: Prepared by:
E5: Reviewed by:
A7: WP B6.2 - Non-deductible per diem allowance
A26: 1. Approach guidance | F26: Completed | G26: Reviewed
A28: 1.1 | B28: Check if the Company paid per diem allowance to its staff when travelling on business trips. If YES, check such payment | F28: o | G28: o
B29: is clealry stated in the Company's internal policies, and supported by legitimate supporting documents (e.g. receipts).
B30: If YES, check if the per-diem payment exceeds the statutory level. If YES, add back the exceeding amount into the
B31: Company's taxable income for CIT purposes
B32: [Please include further comments for manager's attention and decision]
A34: 2. Proposed adjustment
A36: No. | B36: Description | C36: Amount | D36: Source | E36: Notes
A37: 1 | B37: Capped per-diem allowance for CIT purposes | D37: A separate calculation sheet is needed
A38: 2 | B38: Total per-diem allowance charged to P/L | C38: 0 | D38: P/L
A39: 3 | B39: Non-deductible per-diem allowance for CIT purposes | C39: =IF(C38>C37,C38-C37,0) -> 0
A41: 3. Proposed action
A42: The non-deductible per diem allowance must be posted to Item B6 of the CIT return.

Sheet B8
A1: ABCD | G1: WP-B8
A3: Company name: | F3: Name | G3: Date
A4: Period: | E4: Prepared by:
E5: Reviewed by:
A7: Item B8 - Income not subject to CIT
A37: 1. Approach guidance | G37: Completed | H37: Reviewed
A39: 1.1 | B39: Review the Company's investment certificate and discuss with its management to undertand | G39: o | H39: o
B40: its rergistered and actual business activities
B41: Please provide further comments here (if any)
A43: 1.2 | B43: Determine if the Company has business activities which are not subject to CIT. If YES, quantify | G43: o | H43: o
B44: the revenue of its business activities not subject to CIT
A46: 2. Proposed adjustment
A48: No. | B48: Description of adjustment | C48: Amount | D48: Source | E48: Notes
A49: 1 | C49: 0
A50: 2 | C50: 0
A51: 3 | C51: 0
A52: 4 | C52: 0
B53: Total | C53: =SUM(C49:C52) -> 0
A55: 3. Proposed action
A56: The total value presented in this worksheet must be posted to Item B8 of the CIT finalisation return.

Sheet B9
A1: ABCD | H1: WP-B9
A3: Company name: | G3: Name | H3: Date
A4: Period: | F4: Prepared by:
F5: Reviewed by:
A7: Item B9 - Reduction of revenue recognised in the previous fiscal year
A13: 1. Approach guidance | G13: Completed | H13: Reviewed
A15: 1.1 | B15: Obtain the Company's CIT finalisation return of the previous year and determine whether there is | G15: o | H15: o
B16: any of the Company's revenue which relates to current year, but was included in previous
B17: year for CIT purposes
A19: 1.2 | B19: If answer to Point 1.1 is YES, include the same amount into Item B9 of the CIT finalisation return | G19: o | H19: o
B20: of this year for CIT purposes
A22: 2. Proposed adjustment
A24: No. | B24: Description of adjustment | C24: Amount | D24: Source | E24: Notes
A25: 1 | C25: 0
A26: 2 | C26: 0
A27: 3 | C27: 0
A28: 4 | C28: 0
B29: Total | C29: =SUM(C25:C28) -> 0
A31: 3. Proposed action
A32: The total value presented in this worksheet must be posted to Item B9 of the CIT finalisation return.

Sheet B10
A1: ABCD | H1: WP-B10
A3: Client name: | G3: Name | H3: Date
A4: Period: | F4: Prepared by:
F5: Reviewed by:
A7: Item B10 - Expenses related to incremental adjustment of taxable revenue
A14: 1. Approach guidance | G14: Completed | H14: Reviewed
A16: 1.1 | B16: Check if there is any adjustment to the Company's taxable income at Item B2. If YES, related expenses | G16: o | H16: o
B17: of that income must be included into the Company's deductible expenses of current year
A19: 2. Proposed adjustment
G20: o | H20: o
A21: No. | B21: Description of adjustment | C21: Amount | D21: Source | E21: Notes
A22: 1 | B22: Expenses related to the incremental adjustment of taxable income | C22: 0
B23: Total | C23: =SUM(C22:C22) -> 0
A25: 3. Proposed action
A26: The total value presented in this worksheet must be posted to Item B10 of the CIT finalisation return.

Sheet B11
A1: ABCD | F1: WP-B11
A3: Client name : | E3: Name | F3: Date
A4: Period end: | D4: Prepared by:
D5: Reviewed by:
A7: Item B11 - Other decremental adjustments of taxable income
A23: 1. Approach guidance | E23: Completed | F23: Reviewed
A25: 1.1 | B25: Prepare separate working papers for each adjustment items for this work paper | E25: o | F25: o
A27: 2. Proposed adjustment
B29: No. | C29: Description of adjustment | D29: Amount | E29: Ref. | F29: Notes
B30: 1 | C30: Non-taxable unrealised foreign exchange gains | E30: B11.1
B31: 2 | C31: Other decremental adjustments of taxable income | E31: B11.2
C33: Total | D33: =SUM(D30:D32) -> 0
A35: 3. Proposed action
A36: The total adjustment value presented in this worksheet will be posted to Item B11 of the CIT return.

Sheet B11.1
A1: ABCD | G1: WP-B11.1
A3: Company name : | F3: Name | G3: Date
A4: Period end: | E4: Prepared by:
E5: Reviewed by:
A7: B11.1 - Unrealised foreign exchange gain
A21: 1. Approach guidance | F21: Completed | G21: Reviewed
A23: 1.1 | B23: Check if the Company recorded any unrealised foreign exchange gain due to revaluation of | F23: o | G23: o
B24: its "account payables" denominated in foreign currencies in the current year. If YES,
B25: include such amount into Item B11 of the CIT finalisation return
B26: Please provide further comments here (if any)
A28: 2. Proposed adjustment
A30: No. | B30: Description of adjustment | C30: Amount | D30: Source | E30: Notes
A31: 1 | B31: Unrealised foreign exchange gain due to revaluation of accounts other than "payable accounts" | C31: 0
B32: Total | C32: =SUM(C31:C31) -> 0
A34: 3. Proposed action
A35: The total adjustment value presented in this worksheet must be posted to Item B11 of the CIT return.

Sheet B11.2
A1: ABCD | H1: WP-B11.2
A3: Company name : | G3: Name | H3: Date
A4: Period end: | F4: Prepared by:
F5: Reviewed by:
